Workbook

Sheet README
B1: Oda / Odaamsterderm Hub - Product Taxonomy & Amsterdam Test Data
B2: Version 1 draft, 27 Oct 2026. Test data only - every price, stock level, address, phone, batch, registration number and clinical field is dummy.
B4: Reference date (test 'today') | C4: 46322
C5: Expiry and stock-status formulas in Store_Inventory count days from this date. Change it to re-run scenarios.
B7: HOW THE TAXONOMY WORKS
B8: 1. Category = what it is | C8: Each product has ONE primary category (max 2 levels). Category never encodes animal, life stage, brand or pack size.
B9: 2. Animal type is multi-select | C9: Tag every animal the label covers, at the most specific level that is true (e.g. Albendazole = Cattle + Goats + Sheep). Filtering on a parent (Poultry, Cattle, Goats & Sheep, Fish) must include its children.
B10: 3. Life stage is an attribute | C10: Starter / Grower / Finisher / Laying are no longer sub-categories. They live in life_stages and depend on the animal (a pig 'grower' is LS-PIG-GRW, a chicken grower is LS-POU-GRW).
B11: 4. Pack size is a variant | C11: One product, many SKUs (Vitamix Chick 30 g / 100 g / 250 g). Product names never contain pack size. Cross-seller comparison happens at SKU level.
B12: 5. Brand vs producer vs seller | C12: Brand = name on the pack; producer = who made it; seller/store = who sells it. All three are separate fields.
B13: 6. Category vs regulatory class | C13: Category answers 'what does it do'. regulatory_class + prescription_required answer 'how may it be sold'. Set them from registration status, never from packaging wording.
B14: 7. Price and stock belong to the store | C14: The same SKU can have different prices and stock in Tegeta, Mbeya, Mwanza etc. Nothing price-related sits on the product.
B15: 8. Search uses keywords + use cases | C15: search_keywords (pipe-separated, Kiswahili first) plus use_cases tags. Index 'ngombe' and 'ng'ombe' both. See Search_Keywords tab for the shared dictionary.
B16: 9. Cold chain gating | C16: Products with cold_chain_required=TRUE may only be stocked/fulfilled by stores with cold_chain_capable=TRUE, and delivery must respect it.
B17: 10. Chicks are booked, not stocked | C17: Day-old chicks (C7010) have no Store_Inventory rows. Each hatchery publishes hatch dates with price and fixed capacity in Hatch_Schedule; a date shows FULL when booked >= capacity, as on Oda today. Minimum order 50 chicks.
B19: IMPORT ORDER (foreign keys)
C20: Animal_Types > Life_Stages > Categories > Attributes / Attribute_Values > Search_Keywords > Brands > Sellers > Regions > Stores > Products > Variants > Store_Inventory > Hatch_Schedule. Map_* tabs are for migrating the live catalogue.
B22: TABS
B23: Tab | C23: Purpose (row count in column D) | D23: Rows
B24: Animal_Types | C24: Animal hierarchy (parent/child). | D24: =COUNTA(Animal_Types!A:A)-1 -> 14
B25: Life_Stages | C25: Life stages per animal group. | D25: =COUNTA(Life_Stages!A:A)-1 -> 26
B26: Categories | C26: Category tree with definitions and tie-break rules. 'status_vs_live' shows what changed. | D26: =COUNTA(Categories!A:A)-1 -> 38
B27: Attributes | C27: Every product / variant / store-inventory field: type, required-for, source of allowed values. | D27: =COUNTA(Attributes!A:A)-1 -> 44
B28: Attribute_Values | C28: Allowed values (EN + SW) for every enum attribute. | D28: =COUNTA(Attribute_Values!A:A)-1 -> 118
B29: Search_Keywords | C29: Kiswahili/English search dictionary mapped to categories, animals, use cases and diseases. | D29: =COUNTA(Search_Keywords!A:A)-1 -> 75
B30: Brands | C30: Brands / producers. '(demo)' = fictional, following the live system's convention. | D30: =COUNTA(Brands!A:A)-1 -> 24
B31: Sellers | C31: Amsterdam Group plus the 11 hatcheries migrated from Oda. | D31: =COUNTA(Sellers!A:A)-1 -> 12
B32: Regions | C32: Regions with city centroids (GeoNames). A region can hold several stores. | D32: =COUNTA(Regions!A:A)-1 -> 5
B33: Stores | C33: Amsterdam's 6 stores in 5 regions with bio (EN/SW), coordinates, hours, delivery settings and a distance-to-HQ formula. | D33: =COUNTA(Stores!A:A)-1 -> 6
B34: Products | C34: Catalogue products with all taxonomy fields filled. | D34: =COUNTA(Products!A:A)-1 -> 115
B35: Variants | C35: SKUs: pack size, selling unit, shipping weight, dummy barcode, reference price. | D35: =COUNTA(Variants!A:A)-1 -> 150
B36: Store_Inventory | C36: Stock and price per store per SKU, with formula columns and deliberate test scenarios (column 'test_scenario'). No day-old chicks here. | D36: =COUNTA(Store_Inventory!A:A)-1 -> 605
B37: Hatch_Schedule | C37: Day-old chick availability: hatchery x SKU x hatch date with price, capacity, booked, FULL/Open/Closed status and Oda commission. | D37: =COUNTA(Hatch_Schedule!A:A)-1 -> 87
B38: Map_Categories | C38: Old live categories / animal types > new taxonomy. | D38: =COUNTA(Map_Categories!A:A)-1 -> 25
B39: Map_Live_Products | C39: The 15 products currently in the live shared catalogue > new product, SKU, category and animals. | D39: =COUNTA(Map_Live_Products!A:A)-1 -> 15
B40: Map_Stores_Sellers | C40: Live seller/store names > new records, with decisions needed. | D40: =COUNTA(Map_Stores_Sellers!A:A)-1 -> 7
B41: Map_Oda_Chicks | C41: How each Oda concept (tenants, chick types, hatch schedule, CSV, commission) moves into the catalogue, in migration order, plus the 11 hatcheries x chick types. | D41: =COUNTA(Map_Oda_Chicks!A:A)-1 -> 10
B43: ASSUMPTIONS & TO VERIFY
B44: Branch count | C44: Your message said four branches but listed Tegeta, Posta (both Dar es Salaam), Morogoro, Mbeya, Arusha and Mwanza. This file uses all six stores in five regions; delete rows if fewer are wanted.
B45: Coordinates | C45: Store points are approximate area locations (town centres from GeoNames, adjusted to the named area). Replace with each branch's real map pin before testing delivery routing.
...

Sheet Animal_Types
A1: animal_id | B1: parent_id | C1: slug | D1: name_en | E1: name_sw | F1: status_vs_live | G1: notes
A2: AN-POU | C2: poultry | D2: Poultry | E2: Kuku na ndege wafugwao | F2: Existing | G2: Parent. Filtering on Poultry must include all children.
A3: AN-CHK | B3: AN-POU | C3: chicken | D3: Chicken | E3: Kuku | F3: Existing | G3: Broiler, layer, improved indigenous (Sasso, Kuroiler, Tanbro) are production_purpose values, not separate animals.
A4: AN-OPO | B4: AN-POU | C4: other-poultry | D4: Other poultry (ducks, turkeys, guinea fowl, quail) | E4: Bata, bata mzinga, kanga, kware | F4: Existing
A5: AN-CAT | C5: cattle | D5: Cattle | E5: Ng'ombe | F5: Existing | G5: Parent. Tag a product here when it applies to both dairy and beef.
A6: AN-DCT | B6: AN-CAT | C6: dairy-cattle | D6: Dairy cattle | E6: Ng'ombe wa maziwa | F6: New | G6: Use for dairy meal, milking equipment, dairy semen.
A7: AN-BCT | B7: AN-CAT | C7: beef-cattle | D7: Beef cattle | E7: Ng'ombe wa nyama | F7: New | G7: Use for fattening rations.
A8: AN-GTS | C8: goats-sheep | D8: Goats & Sheep | E8: Mbuzi na kondoo | F8: Existing | G8: Parent.
A9: AN-GOT | B9: AN-GTS | C9: goats | D9: Goats | E9: Mbuzi | F9: New
A10: AN-SHP | B10: AN-GTS | C10: sheep | D10: Sheep | E10: Kondoo | F10: New
A11: AN-PIG | C11: pigs | D11: Pigs | E11: Nguruwe | F11: Existing
A12: AN-FSH | C12: fish-aquaculture | D12: Fish / Aquaculture | E12: Samaki / ufugaji wa samaki | F12: Existing | G12: Parent.
A13: AN-TIL | B13: AN-FSH | C13: tilapia | D13: Tilapia | E13: Sato | F13: New
A14: AN-CAF | B14: AN-FSH | C14: catfish | D14: Catfish | E14: Kambale | F14: New
A15: AN-OTH | C15: other-animals | D15: Other livestock / animals (rabbits, dogs, bees) | E15: Mifugo mingine (sungura, mbwa, nyuki) | F15: Existing

Sheet Life_Stages
A1: life_stage_id | B1: applies_to_animal_id | C1: slug | D1: name_en | E1: name_sw | F1: sort_order | G1: notes
A2: LS-ALL | B2: * | C2: all-stages | D2: All stages | E2: Hatua zote | F2: 0 | G2: Use only when the label genuinely says all ages.
A3: LS-POU-STR | B3: AN-POU | C3: starter | D3: Starter / chick (0-4 wks) | E3: Vifaranga (wiki 0-4) | F3: 1
A4: LS-POU-GRW | B4: AN-POU | C4: grower | D4: Grower | E4: Kuku wanaokua | F4: 2 | G4: Broiler grower and layer pullet grower share this stage; production_purpose separates them.
A5: LS-POU-FIN | B5: AN-POU | C5: finisher | D5: Finisher (broiler) | E5: Kumalizia (kuku wa nyama) | F5: 3
A6: LS-POU-LAY | B6: AN-POU | C6: laying | D6: Laying | E6: Kuku wanaotaga | F6: 4
A7: LS-POU-BRD | B7: AN-POU | C7: breeder | D7: Breeder / parent stock | E7: Kuku wazazi | F7: 5
A8: LS-PIG-CRP | B8: AN-PIG | C8: creep | D8: Piglet / creep (pre-weaning) | E8: Watoto wanaonyonya | F8: 1
A9: LS-PIG-WEA | B9: AN-PIG | C9: weaner | D9: Weaner | E9: Walioachishwa kunyonya | F9: 2
A10: LS-PIG-GRW | B10: AN-PIG | C10: grower | D10: Grower | E10: Wanaokua | F10: 3
A11: LS-PIG-FIN | B11: AN-PIG | C11: finisher | D11: Finisher | E11: Kunenepesha | F11: 4
A12: LS-PIG-SOW | B12: AN-PIG | C12: sow | D12: Sow (gestating / lactating) | E12: Nguruwe jike mzazi | F12: 5
A13: LS-PIG-BOR | B13: AN-PIG | C13: boar | D13: Boar | E13: Nguruwe dume | F13: 6
A14: LS-CAT-CLF | B14: AN-CAT | C14: calf | D14: Calf | E14: Ndama | F14: 1
A15: LS-CAT-HEF | B15: AN-CAT | C15: heifer | D15: Heifer | E15: Mtamba | F15: 2
A16: LS-CAT-LAC | B16: AN-CAT | C16: lactating | D16: Lactating cow | E16: Ng'ombe anayekamuliwa | F16: 3
... A27: LS-FSH-BRD | B27: AN-FSH | C27: broodstock | D27: Broodstock | E27: Samaki wazazi | F27: 4

Sheet Categories
A1: category_id | B1: parent_id | C1: level | D1: slug | E1: name_en | F1: name_sw | G1: includes | H1: excludes_tie_break | I1: extra_required_attributes | J1: status_vs_live | K1: product_count
A2: C10 | C2: 1 | D2: feed | E2: Feed | F2: Vyakula vya mifugo | G2: Anything the animal eats as its ration or that is mixed into the ration. | H2: Water-soluble nutritional products go to Supplements (C20), not Feed. | J2: Existing (restructured) | K2: =IF(C2=1,COUNTIF(Products!$F:$F,A2),COUNTIF(Products!$G:$G,A2)) -> 33
A3: C1010 | B3: C10 | C3: 2 | D3: complete-feed | E3: Complete feed | F3: Chakula kamili | G3: Ready-to-feed rations: starter, grower, finisher, layers mash, dairy meal, pig pellets, fish feed. | H3: Life stage is an attribute, NOT a sub-category. Old Feed>Starter/Grower/Finisher/Layers Mash all map here. | I3: life_stages, crude_protein_pct, form | J3: New (replaces Starter/Grower/Finisher/Layers Mash) | K3: =IF(C3=1,COUNTIF(Products!$F:$F,A3),COUNTIF(Products!$G:$G,A3)) -> 17
A4: C1020 | B4: C10 | C4: 2 | D4: concentrates | E4: Concentrates | F4: Kontsentreti (chakula cha kuchanganya) | G4: Protein/vitamin/mineral concentrates the farmer mixes with an energy source (maize bran, maize). | H4: If it needs mixing at more than ~5% of the ration it is a concentrate; under ~5% it is a premix. | I4: crude_protein_pct, inclusion_or_dosage | J4: Existing | K4: =IF(C4=1,COUNTIF(Products!$F:$F,A4),COUNTIF(Products!$G:$G,A4)) -> 4
A5: C1030 | B5: C10 | C5: 2 | D5: premixes | E5: Premixes & base mixes | F5: Premiksi (vitamini na madini ya kuchanganya) | G5: Vitamin-mineral premixes mixed into feed at low inclusion (typically 0.25-5%). | H5: Vitamins given in drinking water go to C2010. | I5: inclusion_or_dosage | J5: New | K5: =IF(C5=1,COUNTIF(Products!$F:$F,A5),COUNTIF(Products!$G:$G,A5)) -> 3
A6: C1040 | B6: C10 | C6: 2 | D6: raw-materials | E6: Raw materials & ingredients | F6: Malighafi za chakula | G6: Single ingredients: maize bran, maize, sunflower cake, soybean meal, fish meal/dagaa, limestone, DCP. | H6: Usually multi-species: tag every animal it is fed to. | I6: crude_protein_pct | J6: New | K6: =IF(C6=1,COUNTIF(Products!$F:$F,A6),COUNTIF(Products!$G:$G,A6)) -> 7
A7: C1050 | B7: C10 | C7: 2 | D7: forage-fodder | E7: Forage & fodder | F7: Malisho na majani | G7: Hay, silage, pasture/fodder seed and cuttings. | J7: New | K7: =IF(C7=1,COUNTIF(Products!$F:$F,A7),COUNTIF(Products!$G:$G,A7)) -> 2
A8: C20 | C8: 1 | D8: supplements-additives | E8: Supplements & additives | F8: Virutubisho na viongezeo | G8: Nutritional products given on top of the ration, in water or feed. | H8: Category describes what the product does; regulatory_class (separate field) decides how it may be sold. Never infer one from the other. | I8: administration_route, use_cases | J8: Existing (was 'Vitamins & Supplements', now split) | K8: =IF(C8=1,COUNTIF(Products!$F:$F,A8),COUNTIF(Products!$G:$G,A8)) -> 14
A9: C2010 | B9: C20 | C9: 2 | D9: vitamins | E9: Vitamins & multivitamins | F9: Vitamini | G9: Single or multivitamin products incl. water-soluble sachets and injectable vitamins. | H9: If the main claim is electrolytes/heat stress use C2020 even when vitamin C is present. | J9: New | K9: =IF(C9=1,COUNTIF(Products!$F:$F,A9),COUNTIF(Products!$G:$G,A9)) -> 4
A10: C2020 | B10: C20 | C10: 2 | D10: electrolytes | E10: Electrolytes & heat-stress | F10: Elektrolaiti na kinga ya joto | G10: Electrolytes, oral rehydration salts, anti-heat-stress products. | J10: New | K10: =IF(C10=1,COUNTIF(Products!$F:$F,A10),COUNTIF(Products!$G:$G,A10)) -> 2
A11: C2030 | B11: C20 | C11: 2 | D11: minerals-licks | E11: Minerals & licks | F11: Madini na mawe ya kulamba | G11: Mineral licks, blocks and loose mineral mixes for direct feeding. | H11: Feed-mill premixes go to C1030. | J11: New | K11: =IF(C11=1,COUNTIF(Products!$F:$F,A11),COUNTIF(Products!$G:$G,A11)) -> 3
A12: C2040 | B12: C20 | C12: 2 | D12: probiotics-enzymes | E12: Probiotics, enzymes & acidifiers | F12: Probiotiki, vimeng'enya na asidi | G12: Gut-health additives. | J12: New | K12: =IF(C12=1,COUNTIF(Products!$F:$F,A12),COUNTIF(Products!$G:$G,A12)) -> 2
A13: C2050 | B13: C20 | C13: 2 | D13: toxin-binders | E13: Toxin binders | F13: Vifunga sumu ya kuvu | G13: Mycotoxin/aflatoxin binders. | J13: New | K13: =IF(C13=1,COUNTIF(Products!$F:$F,A13),COUNTIF(Products!$G:$G,A13)) -> 1
A14: C2060 | B14: C20 | C14: 2 | D14: amino-acids-tonics | E14: Amino acids & tonics | F14: Amino asidi na tonik | G14: Liver tonics, amino-acid liquids, egg/production boosters. | J14: New | K14: =IF(C14=1,COUNTIF(Products!$F:$F,A14),COUNTIF(Products!$G:$G,A14)) -> 2
A15: C30 | C15: 1 | D15: medicines | E15: Medicines | F15: Dawa za mifugo | G15: Products that treat or prevent disease (excluding vaccines). | H15: Every item needs regulatory_class and prescription_required set before it is listed. | I15: active_ingredients, regulatory_class, prescription_required, withdrawal periods | J15: Existing (now split) | K15: =IF(C15=1,COUNTIF(Products!$F:$F,A15),COUNTIF(Products!$G:$G,A15)) -> 15
A16: C3010 | B16: C30 | C16: 2 | D16: antibiotics | E16: Antibiotics & antibacterials | F16: Viuavijasumu | J16: New | K16: =IF(C16=1,COUNTIF(Products!$F:$F,A16),COUNTIF(Products!$G:$G,A16)) -> 4
A17: C3020 | B17: C30 | C17: 2 | D17: dewormers | E17: Dewormers | F17: Dawa za minyoo | G17: Internal parasite control incl. endectocides (ivermectin). | J17: New | K17: =IF(C17=1,COUNTIF(Products!$F:$F,A17),COUNTIF(Products!$G:$G,A17)) -> 4
A18: C3030 | B18: C30 | C18: 2 | D18: anticoccidials | E18: Anticoccidials | F18: Dawa za kuhara damu (koksidiosisi) | J18: New | K18: =IF(C18=1,COUNTIF(Products!$F:$F,A18),COUNTIF(Products!$G:$G,A18)) -> 2
A19: C3040 | B19: C30 | C19: 2 | D19: external-parasites | E19: External parasite control | F19: Dawa za kupe, chawa na utitiri | G19: Acaricides, dips, sprays, pour-ons, mite/lice powders. | J19: New | K19: =IF(C19=1,COUNTIF(Products!$F:$F,A19),COUNTIF(Products!$G:$G,A19)) -> 3
A20: C3050 | B20: C30 | C20: 2 | D20: wound-care | E20: Wound care & topical | F20: Dawa za vidonda | J20: New | K20: =IF(C20=1,COUNTIF(Products!$F:$F,A20),COUNTIF(Products!$G:$G,A20)) -> 1
A21: C3060 | B21: C30 | C21: 2 | D21: other-medicines | E21: Other medicines | F21: Dawa nyingine | G21: Metabolic (milk fever), anti-inflammatories, hormones etc. | H21: Use sparingly; add a new sub-category once >5 products share a purpose. | J21: New | K21: =IF(C21=1,COUNTIF(Products!$F:$F,A21),COUNTIF(Products!$G:$G,A21)) -> 1
A22: C40 | C22: 1 | D22: vaccines | E22: Vaccines & biologicals | F22: Chanjo | G22: All vaccines. | H22: No sub-categories: animal type + disease_target do the filtering. | I22: disease_target, cold_chain_required, storage | J22: Existing | K22: =IF(C22=1,COUNTIF(Products!$F:$F,A22),COUNTIF(Products!$G:$G,A22)) -> 9
A23: C50 | C23: 1 | D23: biosecurity-hygiene | E23: Biosecurity & hygiene | F23: Usafi na kinga ya shamba | G23: Disinfectants, water sanitisers, foot-dip products, rodent and fly control. | H23: Replaces the undefined 'Veterinary Products' category. | J23: New (replaces 'Veterinary Products') | K23: =IF(C23=1,COUNTIF(Products!$F:$F,A23),COUNTIF(Products!$G:$G,A23)) -> 4
A24: C5010 | B24: C50 | C24: 2 | D24: disinfectants | E24: Disinfectants & sanitisers | F24: Dawa za kuua vijidudu | J24: New | K24: =IF(C24=1,COUNTIF(Products!$F:$F,A24),COUNTIF(Products!$G:$G,A24)) -> 3
A25: C5020 | B25: C50 | C25: 2 | D25: pest-rodent-control | E25: Pest & rodent control | F25: Udhibiti wa panya na wadudu | J25: New | K25: =IF(C25=1,COUNTIF(Products!$F:$F,A25),COUNTIF(Products!$G:$G,A25)) -> 1
A26: C60 | C26: 1 | D26: equipment | E26: Equipment & supplies | F26: Vifaa | G26: Durable goods and consumables. | I26: capacity, power_source where relevant | J26: Existing | K26: =IF(C26=1,COUNTIF(Products!$F:$F,A26),COUNTIF(Products!$G:$G,A26)) -> 19
A27: C6010 | B27: C60 | C27: 2 | D27: feeders-drinkers | E27: Feeders & drinkers | F27: Vyombo vya chakula na maji | J27: Existing | K27: =IF(C27=1,COUNTIF(Products!$F:$F,A27),COUNTIF(Products!$G:$G,A27)) -> 6
A28: C6020 | B28: C60 | C28: 2 | D28: brooding-heating | E28: Brooding & heating | F28: Vifaa vya kulelea vifaranga | J28: Split from 'Housing & Brooding' | K28: =IF(C28=1,COUNTIF(Products!$F:$F,A28),COUNTIF(Products!$G:$G,A28)) -> 2
A29: C6030 | B29: C60 | C29: 2 | D29: housing-cages | E29: Housing, cages & nests | F29: Mabanda, vizimba na viota | J29: Split from 'Housing & Brooding' | K29: =IF(C29=1,COUNTIF(Products!$F:$F,A29),COUNTIF(Products!$G:$G,A29)) -> 2
A30: C6040 | B30: C60 | C30: 2 | D30: incubators | E30: Incubators & hatching | F30: Mashine za kutotolesha | J30: New | K30: =IF(C30=1,COUNTIF(Products!$F:$F,A30),COUNTIF(Products!$G:$G,A30)) -> 2
A31: C6050 | B31: C60 | C31: 2 | D31: egg-handling | E31: Egg handling & packaging | F31: Trei na vifungashio vya mayai | J31: New | K31: =IF(C31=1,COUNTIF(Products!$F:$F,A31),COUNTIF(Products!$G:$G,A31)) -> 1
A32: C6060 | B32: C60 | C32: 2 | D32: vet-tools | E32: Veterinary tools | F32: Vifaa vya tiba ya mifugo | G32: Syringes, needles, drenching guns, thermometers. | J32: New | K32: =IF(C32=1,COUNTIF(Products!$F:$F,A32),COUNTIF(Products!$G:$G,A32)) -> 4
A33: C6070 | B33: C60 | C33: 2 | D33: milking-dairy | E33: Milking & dairy equipment | F33: Vifaa vya kukamua na maziwa | J33: New | K33: =IF(C33=1,COUNTIF(Products!$F:$F,A33),COUNTIF(Products!$G:$G,A33)) -> 1
A34: C6080 | B34: C60 | C34: 2 | D34: weighing | E34: Weighing & measuring | F34: Mizani na vipimo | J34: New | K34: =IF(C34=1,COUNTIF(Products!$F:$F,A34),COUNTIF(Products!$G:$G,A34)) -> 1
A35: C70 | C35: 1 | D35: live-animals-genetics | E35: Live animals & genetics | F35: Mifugo hai na mbegu | G35: Animals and genetic material. | H35: Decided: day-old chicks move into this catalogue. They are sold against hatch dates (Hatch_Schedule), not shelf stock; other live animals use Store_Inventory. | I35: breed_strain, vaccination_status | J35: New | K35: =IF(C35=1,COUNTIF(Products!$F:$F,A35),COUNTIF(Products!$G:$G,A35)) -> 21
A36: C7010 | B36: C70 | C36: 2 | D36: day-old-chicks | E36: Day-old chicks & hatching eggs | F36: Vifaranga na mayai ya kutotolesha | G36: One product per hatchery x chick type (e.g. 'Kibo Broiler Day-old Chicks'). Replaces Oda's chick-type list. | H36: Availability, price and capacity live on Hatch_Schedule rows; never put chicks in Store_Inventory. | I36: breed_strain, min_order_qty, hatch schedule | J36: New (absorbs Oda chick booking) | K36: =IF(C36=1,COUNTIF(Products!$F:$F,A36),COUNTIF(Products!$G:$G,A36)) -> 17
A37: C7020 | B37: C70 | C37: 2 | D37: young-stock | E37: Young stock | F37: Mifugo wachanga | G37: Piglets, calves, kids, fingerlings, point-of-lay pullets. | J37: New | K37: =IF(C37=1,COUNTIF(Products!$F:$F,A37),COUNTIF(Products!$G:$G,A37)) -> 3
A38: C7030 | B38: C70 | C38: 2 | D38: breeding-stock | E38: Breeding & mature stock | F38: Mifugo wazazi na waliokomaa | J38: New | K38: =IF(C38=1,COUNTIF(Products!$F:$F,A38),COUNTIF(Products!$G:$G,A38)) -> 0
A39: C7040 | B39: C70 | C39: 2 | D39: semen-ai | E39: Semen & AI | F39: Mbegu za uhimilishaji | I39: cold_chain_required | J39: New | K39: =IF(C39=1,COUNTIF(Products!$F:$F,A39),COUNTIF(Products!$G:$G,A39)) -> 1

Sheet Attributes
A1: attribute_key | B1: label_en | C1: label_sw | D1: level | E1: data_type | F1: multi_select | G1: required_for | H1: allowed_values_source | I1: notes
A2: animal_types | B2: Animal type(s) | C2: Aina ya mifugo | D2: product | E2: enum | F2: Y | G2: ALL | H2: Animal_Types | I2: MULTI-SELECT. Tag the most specific level that is true; parent filters include children.
A3: life_stages | B3: Life stage(s) | C3: Hatua ya ukuaji | D3: product | E3: enum | F3: Y | G3: C1010, C1020, C70 | H3: Life_Stages | I3: Only stages belonging to the chosen animal types.
A4: production_purpose | B4: Production purpose | C4: Lengo la ufugaji | D4: product | E4: enum | F4: Y | G4: C1010, C1020, C70 (optional elsewhere) | H4: Attribute_Values | I4: broiler / layer / improved indigenous / dairy / beef ...
A5: form | B5: Physical form | C5: Umbo | D5: product | E5: enum | F5: N | G5: ALL | H5: Attribute_Values
A6: administration_route | B6: How it is given | C6: Jinsi ya kutumia | D6: product | E6: enum | F6: Y | G6: C20, C30, C40, C50 | H6: Attribute_Values
A7: use_cases | B7: Problem / use case tags | C7: Tatizo / matumizi | D7: product | E7: enum | F7: Y | G7: Recommended for all; required C20, C30 | H7: Attribute_Values | I7: Powers problem-based search (e.g. 'joto' finds heat-stress products).
A8: disease_target | B8: Disease(s) targeted | C8: Ugonjwa unaolengwa | D8: product | E8: enum | F8: Y | G8: C40 (required); C30 (optional) | H8: Attribute_Values
A9: active_ingredients | B9: Active ingredients / composition | C9: Viambato | D9: product | E9: text | F9: N | G9: C20, C30, C40, C50 | H9: free text | I9: As printed on label.
A10: crude_protein_pct | B10: Crude protein % | C10: Protini % | D10: product | E10: number | F10: N | G10: C1010, C1020, C1040 | I10: Decimal number, e.g. 22.
A11: inclusion_or_dosage | B11: Inclusion rate / dosage | C11: Kiwango cha kuchanganya / dozi | D11: product | E11: text | F11: N | G11: C1020, C1030, C20, C30 | H11: free text | I11: Copy from label; never invent.
A12: withdrawal_meat_days | B12: Withdrawal - meat (days) | C12: Muda wa kusubiri - nyama | D12: product | E12: integer | F12: N | G12: C30 (where applicable) | I12: From label only.
A13: withdrawal_eggs_days | B13: Withdrawal - eggs (days) | C13: Muda wa kusubiri - mayai | D13: product | E13: integer | F13: N | G13: C30 poultry | I13: From label only.
A14: withdrawal_milk_days | B14: Withdrawal - milk (days) | C14: Muda wa kusubiri - maziwa | D14: product | E14: integer | F14: N | G14: C30 dairy | I14: From label only.
A15: regulatory_class | B15: Regulatory class | C15: Kundi la udhibiti | D15: product | E15: enum | F15: N | G15: ALL | H15: Attribute_Values | I15: Set from registration status, not from packaging wording.
A16: prescription_required | B16: Prescription / vet supervision required | C16: Inahitaji cheti cha daktari | D16: product | E16: boolean | F16: N | G16: C30, C40 | I16: If TRUE: checkout must collect prescription or route to vet; decide flow before go-live.
A17: registration_no | B17: Registration number | C17: Namba ya usajili | D17: product | E17: text | F17: N | G17: Regulated classes | I17: Dummy values in this file start DEMO-.
A18: cold_chain_required | B18: Cold chain required | C18: Inahitaji ubaridi | D18: product | E18: boolean | F18: N | G18: C40, C7040, some C30 | I18: Only stores with cold_chain_capable=TRUE may stock/fulfil.
A19: storage | B19: Storage conditions | C19: Uhifadhi | D19: product | E19: text | F19: N | G19: C20, C30, C40
A20: capacity | B20: Capacity / size | C20: Ujazo / ukubwa | D20: product | E20: text | F20: N | G20: C60 | I20: e.g. 10 L, 528 eggs, 96 birds.
A21: power_source | B21: Power source | C21: Chanzo cha nishati | D21: product | E21: enum | F21: N | G21: C6020, C6040 | H21: Attribute_Values
A22: breed_strain | B22: Breed / strain | C22: Aina / mbegu | D22: product | E22: text | F22: N | G22: C70
A23: brand_id | B23: Brand | C23: Chapa | D23: product | E23: fk | F23: N | G23: ALL | H23: Brands | I23: Brand = name on the pack.
A24: producer_id | B24: Producer / manufacturer | C24: Mtengenezaji | D24: product | E24: fk | F24: N | G24: Optional | H24: Brands | I24: Who made it. May differ from brand owner and from the seller.
A25: search_keywords | B25: Search keywords (SW/EN) | C25: Maneno ya utafutaji | D25: product | E25: text (pipe-separated) | F25: Y | G25: ALL | H25: Search_Keywords + free | I25: Kiswahili names, local names, problems solved.
A26: pack_size_value | B26: Pack size value | C26: Ukubwa wa kifurushi | D26: variant | E26: number | F26: N | G26: ALL variants | I26: Pack size lives on the VARIANT, never in the product name.
A27: pack_size_unit | B27: Pack size unit | C27: Kipimo | D27: variant | E27: enum | F27: N | G27: ALL variants | H27: Attribute_Values
A28: selling_unit | B28: Selling unit | C28: Kipimo cha kuuzia | D28: variant | E28: enum | F28: N | G28: ALL variants | H28: Attribute_Values | I28: Matches the live 'Selling unit' list plus bird/head/straw.
A29: net_weight_kg | B29: Shipping weight (kg) | C29: Uzito wa usafirishaji | D29: variant | E29: number | F29: N | G29: ALL variants | I29: Needed for delivery cost.
A30: gtin | B30: Barcode (GTIN-13) | C30: Msimbo pau | D30: variant | E30: text | F30: N | G30: Optional | I30: Dummy codes use the 200-299 in-store prefix.
A31: qty_on_hand | B31: Quantity on hand | C31: Idadi iliyopo | D31: store_inventory | E31: integer | F31: N | G31: ALL
A32: reorder_level | B32: Reorder level | C32: Kiwango cha kuagiza tena | D32: store_inventory | E32: integer | F32: N | G32: ALL | I32: Drives 'Low stock'.
A33: cost_price_tzs | B33: Cost price (TZS) | C33: Bei ya kununua | D33: store_inventory | E33: integer | F33: N | G33: ALL
A34: selling_price_tzs | B34: Selling price (TZS) | C34: Bei ya kuuza | D34: store_inventory | E34: integer | F34: N | G34: ALL | I34: Price is per STORE, so regions can differ.
A35: batch_no | B35: Batch number | C35: Namba ya batch | D35: store_inventory | E35: text | F35: N | G35: Perishables
A36: expiry_date | B36: Expiry date | C36: Tarehe ya kuisha muda | D36: store_inventory | E36: date | F36: N | G36: C10, C20, C30, C40, C50 | I36: Drives 'Expiring soon'; expired stock must not be sold.
A37: listed_online | B37: Listed online | C37: Imewekwa mtandaoni | D37: store_inventory | E37: boolean | F37: N | G37: ALL
A38: online_qty | B38: Units exposed online | C38: Idadi mtandaoni | D38: store_inventory | E38: integer | F38: N | G38: ALL | I38: <= qty_on_hand.
A39: min_order_qty | B39: Minimum order quantity | C39: Kiwango cha chini cha oda | D39: variant | E39: integer | F39: N | G39: ALL variants (50 for day-old chicks) | I39: Checkout must enforce it.
A40: hatch_date | B40: Hatch date | C40: Tarehe ya kutotoa | D40: hatch_schedule | E40: date | F40: N | G40: C7010 | I40: One row per seller x SKU x hatch date (Oda hatch schedule).
...

Sheet Attribute_Values
A1: attribute_key | B1: value_code | C1: label_en | D1: label_sw
A2: production_purpose | B2: broiler | C2: Broiler (meat) | D2: Kuku wa nyama
A3: production_purpose | B3: layer | C3: Layer (eggs) | D3: Kuku wa mayai
A4: production_purpose | B4: improved_indigenous | C4: Improved indigenous (Sasso, Kuroiler, Tanbro) | D4: Kuku chotara / kienyeji kilichoboreshwa
A5: production_purpose | B5: breeder | C5: Breeder / parent stock | D5: Wazazi
A6: production_purpose | B6: dairy | C6: Dairy | D6: Maziwa
A7: production_purpose | B7: beef | C7: Beef | D7: Nyama ya ng'ombe
A8: production_purpose | B8: meat_small_ruminant | C8: Meat (goats/sheep) | D8: Nyama (mbuzi/kondoo)
A9: production_purpose | B9: pork | C9: Pork | D9: Nyama ya nguruwe
A10: production_purpose | B10: table_fish | C10: Table fish | D10: Samaki wa chakula
A11: production_purpose | B11: general | C11: General / multi-purpose | D11: Matumizi ya jumla
A12: form | B12: mash | C12: Mash | D12: Unga
... A119: selling_unit | B119: set | C119: set | D119: seti

Sheet Search_Keywords
A1: term | B1: language | C1: maps_to_type | D1: maps_to_id | E1: notes
A2: kuku | B2: sw | C2: animal | D2: AN-CHK
A3: vifaranga | B3: sw | C3: category | D3: C7010 | E3: Also boosts starter feed (LS-POU-STR).
A4: kuku wa nyama | B4: sw | C4: production_purpose | D4: broiler
A5: broila | B5: sw | C5: production_purpose | D5: broiler | E5: Common Swahili spelling
A6: kuku wa mayai | B6: sw | C6: production_purpose | D6: layer
A7: leya | B7: sw | C7: production_purpose | D7: layer | E7: Common Swahili spelling
A8: kuku wa kienyeji | B8: sw | C8: production_purpose | D8: improved_indigenous
A9: chotara | B9: sw | C9: production_purpose | D9: improved_indigenous
A10: bata | B10: sw | C10: animal | D10: AN-OPO
A11: ng'ombe | B11: sw | C11: animal | D11: AN-CAT | E11: Also index 'ngombe' without apostrophe
A12: ng'ombe wa maziwa | B12: sw | C12: animal | D12: AN-DCT
A13: mbuzi | B13: sw | C13: animal | D13: AN-GOT
A14: kondoo | B14: sw | C14: animal | D14: AN-SHP
A15: nguruwe | B15: sw | C15: animal | D15: AN-PIG
A16: samaki | B16: sw | C16: animal | D16: AN-FSH
A17: sato | B17: sw | C17: animal | D17: AN-TIL
A18: kambale | B18: sw | C18: animal | D18: AN-CAF
A19: sungura | B19: sw | C19: animal | D19: AN-OTH
A20: chakula | B20: sw | C20: category | D20: C10
A21: chakula cha kuku | B21: sw | C21: category+animal | D21: C10|AN-CHK
A22: pumba | B22: sw | C22: product_term | D22: maize bran | E22: Raw material C1040
A23: mashudu | B23: sw | C23: product_term | D23: sunflower cake | E23: Raw material C1040
A24: soya | B24: sw | C24: product_term | D24: soybean meal
A25: dagaa | B25: sw | C25: product_term | D25: fish meal
A26: chokaa | B26: sw | C26: product_term | D26: limestone
A27: mahindi | B27: sw | C27: product_term | D27: maize
A28: majani makavu | B28: sw | C28: product_term | D28: hay | E28: C1050
A29: kontsentreti | B29: sw | C29: category | D29: C1020 | E29: Also 'concentrate'
A30: premiksi | B30: sw | C30: category | D30: C1030
A31: vitamini | B31: sw | C31: category | D31: C2010
A32: madini | B32: sw | C32: category | D32: C2030
A33: jiwe la chumvi | B33: sw | C33: category | D33: C2030 | E33: Mineral lick
A34: dawa | B34: sw | C34: category | D34: C30
A35: dawa ya minyoo | B35: sw | C35: category | D35: C3020
A36: minyoo | B36: sw | C36: use_case | D36: worms
A37: kupe | B37: sw | C37: use_case | D37: ticks
A38: utitiri | B38: sw | C38: use_case | D38: mites_lice
A39: chawa | B39: sw | C39: use_case | D39: mites_lice
A40: kuhara damu | B40: sw | C40: use_case | D40: coccidiosis
...

Sheet Brands
A1: brand_id | B1: name | C1: role | D1: country | E1: is_demo | F1: notes
A2: BR-AMS | B2: Amsterdam Group | C2: Brand owner / distributor / feed manufacturer | D2: Tanzania | E2: FALSE | F2: Real seller. Pig concentrate is made in Tegeta-Wazo per bag label; Vitamix/Clear Heat sachets are made by a contract manufacturer in China per label.
A3: BR-SIL | B3: Silverlands | C3: Manufacturer (feed, day-old chicks) | D3: Tanzania | E3: FALSE | F3: Already a producer in the live system. Products/prices here are dummy.
A4: BR-BORA | B4: Bora Feeds (demo) | C4: Manufacturer (feed) | D4: Tanzania | E4: TRUE | F4: Already in the live system as a demo producer.
A5: BR-SHF | B5: Shamba Feeds (demo) | C5: Manufacturer (feed) | D5: Tanzania | E5: TRUE | F5: Fictional.
A6: BR-ULU | B6: Uluguru Agro (demo) | C6: Manufacturer (ruminant feed, licks) | D6: Tanzania | E6: TRUE | F6: Fictional.
A7: BR-ZWA | B7: Ziwa Aqua (demo) | C7: Manufacturer (fish feed, fingerlings) | D7: Tanzania | E7: TRUE | F7: Fictional.
A8: BR-NYR | B8: Nyanda Raw Materials (demo) | C8: Supplier (raw materials) | D8: Tanzania | E8: TRUE | F8: Fictional.
A9: BR-NYN | B9: Nyanda Nutrition (demo) | C9: Manufacturer (premixes, additives) | D9: Tanzania | E9: TRUE | F9: Fictional.
A10: BR-KLV | B10: KiliVet (demo) | C10: Manufacturer (supplements) | D10: Kenya | E10: TRUE | F10: Fictional.
A11: BR-AFM | B11: Afya Mifugo Pharma (demo) | C11: Manufacturer (veterinary medicines) | D11: India | E11: TRUE | F11: Fictional.
A12: BR-KNG | B12: Kinga Vaccines (demo) | C12: Manufacturer (vaccines) | D12: Tanzania | E12: TRUE | F12: Fictional.
... A25: BR-INTR | B25: Interchick | C25: Hatchery (day-old chicks) | D25: Tanzania | E25: FALSE | F25: Oda supplier migrated into the catalogue. Chick types as on Oda; prices and capacities in this file are dummy.

Sheet Sellers
A1: seller_id | B1: seller_type | C1: display_name | D1: legal_name | E1: website | F1: hq_phone | G1: hq_store_id | H1: status | I1: notes
A2: SEL-AMS | B2: Agrovet (multi-store) | C2: Amsterdam Group | D2: Amsterdam Group (legal name to confirm) | E2: www.amsterdamgroup.co.tz | F2: +255 622 531 253 | G2: ST-AMS-TEG | H2: active | I2: Website and phone as printed on the Amsterdam product catalogue. Live system currently spells the seller 'Amsterderm Group' and stores 'Amsterdem Group' - standardise to 'Amsterdam'.
A3: SEL-KIBO | B3: Hatchery | C3: Kibo | D3: Kibo (legal name to confirm) | H3: migrate from Oda tenant | I3: Hatchery seller. Was Oda tenant at kibo.oda.co.tz (slug pattern assumed from kibo.oda.co.tz). Map its Selcom merchant account; Oda commission is charged per chick.
A4: SEL-HARS | B4: Hatchery | C4: Harsho | D4: Harsho (legal name to confirm) | H4: migrate from Oda tenant | I4: Hatchery seller. Was Oda tenant at harsho.oda.co.tz (slug pattern assumed from kibo.oda.co.tz). Map its Selcom merchant account; Oda commission is charged per chick.
A5: SEL-BACK | B5: Hatchery | C5: Backbone | D5: Backbone (legal name to confirm) | H5: migrate from Oda tenant | I5: Hatchery seller. Was Oda tenant at backbone.oda.co.tz (slug pattern assumed from kibo.oda.co.tz). Map its Selcom merchant account; Oda commission is charged per chick.
A6: SEL-IRVN | B6: Hatchery | C6: Irvines | D6: Irvines (legal name to confirm) | H6: migrate from Oda tenant | I6: Hatchery seller. Was Oda tenant at irvines.oda.co.tz (slug pattern assumed from kibo.oda.co.tz). Map its Selcom merchant account; Oda commission is charged per chick.
A7: SEL-ORGN | B7: Hatchery | C7: Organia | D7: Organia (legal name to confirm) | H7: migrate from Oda tenant | I7: Hatchery seller. Was Oda tenant at organia.oda.co.tz (slug pattern assumed from kibo.oda.co.tz). Map its Selcom merchant account; Oda commission is charged per chick.
A8: SEL-HAPP | B8: Hatchery | C8: Happy Chicks | D8: Happy Chicks (legal name to confirm) | H8: migrate from Oda tenant | I8: Hatchery seller. Was Oda tenant at happychicks.oda.co.tz (slug pattern assumed from kibo.oda.co.tz). Map its Selcom merchant account; Oda commission is charged per chick.
A9: SEL-CENT | B9: Hatchery | C9: Central Chicks (Animal Care) | D9: Central Chicks (Animal Care) (legal name to confirm) | H9: migrate from Oda tenant | I9: Hatchery seller. Was Oda tenant at centralchicks.oda.co.tz (slug pattern assumed from kibo.oda.co.tz). Map its Selcom merchant account; Oda commission is charged per chick.
A10: SEL-TPF | B10: Hatchery | C10: Tanzania Poultry Farms | D10: Tanzania Poultry Farms (legal name to confirm) | H10: migrate from Oda tenant | I10: Hatchery seller. Was Oda tenant at tpf.oda.co.tz (slug pattern assumed from kibo.oda.co.tz). Map its Selcom merchant account; Oda commission is charged per chick.
A11: SEL-MKUZ | B11: Hatchery | C11: Mkuza Chicks | D11: Mkuza Chicks (legal name to confirm) | H11: migrate from Oda tenant | I11: Hatchery seller. Was Oda tenant at mkuza.oda.co.tz (slug pattern assumed from kibo.oda.co.tz). Map its Selcom merchant account; Oda commission is charged per chick.
A12: SEL-INTR | B12: Hatchery | C12: Interchick | D12: Interchick (legal name to confirm) | H12: migrate from Oda tenant | I12: Hatchery seller. Was Oda tenant at interchick.oda.co.tz (slug pattern assumed from kibo.oda.co.tz). Map its Selcom merchant account; Oda commission is charged per chick.
A13: SEL-SIL | B13: Hatchery | C13: Silverlands | D13: Silverlands (legal name to confirm) | H13: migrate from Oda tenant | I13: Hatchery seller. Was Oda tenant at silverlands.oda.co.tz (slug pattern assumed from kibo.oda.co.tz). Map its Selcom merchant account; Oda commission is charged per chick.

Sheet Regions
A1: region_id | B1: region_name | C1: centroid_lat | D1: centroid_lng | E1: zone | F1: store_count
A2: REG-DAR | B2: Dar es Salaam | C2: -6.823 | D2: 39.27 | E2: Coastal | F2: =COUNTIF(Stores!$E:$E,A2) -> 2
A3: REG-MOR | B3: Morogoro | C3: -6.821 | D3: 37.661 | E3: Eastern / central corridor | F3: =COUNTIF(Stores!$E:$E,A3) -> 1
A4: REG-MBY | B4: Mbeya | C4: -8.9 | D4: 33.45 | E4: Southern Highlands | F4: =COUNTIF(Stores!$E:$E,A4) -> 1
A5: REG-ARU | B5: Arusha | C5: -3.367 | D5: 36.683 | E5: Northern | F5: =COUNTIF(Stores!$E:$E,A5) -> 1
A6: REG-MWZ | B6: Mwanza | C6: -2.517 | D6: 32.9 | E6: Lake Zone | F6: =COUNTIF(Stores!$E:$E,A6) -> 1

Sheet Stores
A1: store_id | B1: store_code | C1: seller_id | D1: store_name | E1: region_id | F1: district | G1: area | H1: street_address | I1: landmark | J1: latitude | K1: longitude | L1: store_type | M1: is_hq | N1: phone | O1: whatsapp | P1: email | Q1: opening_hours | R1: manager | S1: delivery_radius_km | T1: delivery_base_fee_tzs | U1: delivery_fee_per_km_tzs | V1: cold_chain_capable | W1: pickup_available | X1: vet_advice_on_site | Y1: bio_en | Z1: bio_sw | AA1: km_to_hq_straight_line
A2: ST-AMS-TEG | B2: TEG | C2: SEL-AMS | D2: Amsterdam Group - Tegeta (HQ & Warehouse) | E2: REG-DAR | F2: Kinondoni | G2: Tegeta / Wazo | H2: Bagamoyo Road, Tegeta-Wazo (demo address) | I2: Near Tegeta bus stand (demo) | J2: -6.6465 | K2: 39.2112 | L2: Flagship + central warehouse | M2: TRUE | N2: +255 622 531 253 | O2: +255 622 531 253 | P2: tegeta.amsterdam@example.com | Q2: Mon-Sat 07:30-18:30; Sun 09:00-14:00 | R2: Neema Mushi (demo) | S2: 30 | T2: 5000 | U2: 500 | V2: TRUE | W2: TRUE | X2: TRUE | Y2: Amsterdam Group's head office and main warehouse in Tegeta-Wazo, serving poultry and pig farmers across northern Dar es Salaam and Bagamoyo. Full range of feeds, concentrates, supplements, animal health products and equipment, with same-day delivery within 30 km and a livestock officer on site for advice. | Z2: Ofisi kuu na ghala kuu la Amsterdam Group lililopo Tegeta-Wazo, likiwahudumia wafugaji wa kuku na nguruwe wa kaskazini mwa Dar es Salaam na Bagamoyo. Tuna vyakula, kontsentreti, virutubisho, dawa na vifaa vya mifugo, pamoja na usafirishaji wa siku hiyo hiyo ndani ya kilomita 30 na afisa mifugo wa kukushauri. | AA2: =ROUND(6371*ACOS(MIN(1,COS(RADIANS(90-J2))*COS(RADIANS(90-$J$2))+SIN(RADIANS(90-J2))*SIN(RADIANS(90-$J$2))*COS(RADIANS(K2-$K$2)))),1) -> 0
A3: ST-AMS-PST | B3: PST | C3: SEL-AMS | D3: Amsterdam Group - Posta (City Centre) | E3: REG-DAR | F3: Ilala | G3: Posta / Kisutu | H3: Azikiwe Street, Posta (demo address) | I3: Near Posta Mpya (demo) | J3: -6.8163 | K3: 39.2886 | L3: City-centre outlet (small format) | M3: FALSE | N3: +255 700 000 102 | O3: +255 700 000 102 | P3: posta.amsterdam@example.com | Q3: Mon-Fri 08:00-17:30; Sat 08:30-14:00; Sun closed | R3: Juma Said (demo) | S3: 15 | T3: 4000 | U3: 600 | V3: TRUE | W3: TRUE | X3: FALSE | Y3: Compact city-centre outlet in Posta for vaccines, medicines, vitamins and small equipment. Vaccines are kept in a monitored 2-8 C fridge. Bulk feed ordered here is delivered from the Tegeta warehouse. | Z3: Duka dogo katikati ya jiji, Posta, kwa chanjo, dawa, vitamini na vifaa vidogo. Chanjo huhifadhiwa kwenye friji ya nyuzi joto 2-8 inayofuatiliwa. Vyakula vya jumla vinavyoagizwa hapa husafirishwa kutoka ghala la Tegeta. | AA3: =ROUND(6371*ACOS(MIN(1,COS(RADIANS(90-J3))*COS(RADIANS(90-$J$2))+SIN(RADIANS(90-J3))*SIN(RADIANS(90-$J$2))*COS(RADIANS(K3-$K$2)))),1) -> 20.7
A4: ST-AMS-MOR | B4: MOR | C4: SEL-AMS | D4: Amsterdam Group - Morogoro | E4: REG-MOR | F4: Morogoro Municipal | G4: Mji Mkuu / Main Market | H4: Boma Road, Morogoro (demo address) | I4: Near Morogoro central market (demo) | J4: -6.8243 | K4: 37.6618 | L4: Regional branch | M4: FALSE | N4: +255 700 000 103 | O4: +255 700 000 103 | P4: morogoro.amsterdam@example.com | Q4: Mon-Sat 07:30-18:00; Sun closed | R4: Rehema Mlay (demo) | S4: 25 | T4: 4000 | U4: 500 | V4: TRUE | W4: TRUE | X4: TRUE | Y4: Branch on the Dar-Dodoma corridor serving poultry, pig and dairy farmers in Morogoro Municipality, Mvomero and Kilosa. Stocks feeds, raw materials, supplements, vaccines and animal health products, with delivery within 25 km. | Z4: Tawi lililopo kwenye barabara ya Dar-Dodoma, likiwahudumia wafugaji wa kuku, nguruwe na ng'ombe wa maziwa wa Manispaa ya Morogoro, Mvomero na Kilosa. Tuna vyakula, malighafi, virutubisho, chanjo na dawa za mifugo, pamoja na usafirishaji ndani ya kilomita 25. | AA4: =ROUND(6371*ACOS(MIN(1,COS(RADIANS(90-J4))*COS(RADIANS(90-$J$2))+SIN(RADIANS(90-J4))*SIN(RADIANS(90-$J$2))*COS(RADIANS(K4-$K$2)))),1) -> 172.2
A5: ST-AMS-MBY | B5: MBY | C5: SEL-AMS | D5: Amsterdam Group - Mbeya | E5: REG-MBY | F5: Mbeya City | G5: Mwanjelwa | H5: Tanzam Highway, Mwanjelwa (demo address) | I5: Near Mwanjelwa market (demo) | J5: -8.9068 | K5: 33.4512 | L5: Regional branch | M5: FALSE | N5: +255 700 000 104 | O5: +255 700 000 104 | P5: mbeya.amsterdam@example.com | Q5: Mon-Sat 08:00-18:00; Sun closed | R5: Baraka Mwakyusa (demo) | S5: 30 | T5: 5000 | U5: 600 | V5: TRUE | W5: TRUE | X5: TRUE | Y5: Southern Highlands branch serving pig and dairy farmers in Mbeya City, Mbalizi and Rungwe, plus a growing broiler market. Strong on pig concentrates, locally sourced raw materials such as maize bran and sunflower cake, and cattle health products. | Z5: Tawi la Nyanda za Juu Kusini linalowahudumia wafugaji wa nguruwe na ng'ombe wa maziwa wa Jiji la Mbeya, Mbalizi na Rungwe, pamoja na wafugaji wa kuku wa nyama. Tuna kontsentreti za nguruwe, malighafi za ndani kama pumba na mashudu ya alizeti, na dawa za ng'ombe. | AA5: =ROUND(6371*ACOS(MIN(1,COS(RADIANS(90-J5))*COS(RADIANS(90-$J$2))+SIN(RADIANS(90-J5))*SIN(RADIANS(90-$J$2))*COS(RADIANS(K5-$K$2)))),1) -> 682.5
A6: ST-AMS-ARU | B6: ARU | C6: SEL-AMS | D6: Amsterdam Group - Arusha | E6: REG-ARU | F6: Arusha City | G6: Kilombero / Sokoine Road | H6: Sokoine Road, Arusha (demo address) | I6: Near Kilombero market (demo) | J6: -3.3745 | K6: 36.6862 | L6: Regional branch | M6: FALSE | N6: +255 700 000 105 | O6: +255 700 000 105 | P6: arusha.amsterdam@example.com | Q6: Mon-Sat 07:30-18:00; Sun 09:00-13:00 | R6: Lightness Laizer (demo) | S6: 30 | T6: 5000 | U6: 600 | V6: TRUE | W6: TRUE | X6: TRUE | Y6: Northern zone branch serving layer and dairy farmers in Arusha City, Arumeru and along the Moshi road. Wide range of layer feeds, dairy meal, mineral licks, tick control and cold-stored vaccines, plus dairy semen for AI technicians. | Z6: Tawi la Kanda ya Kaskazini linalowahudumia wafugaji wa kuku wa mayai na ng'ombe wa maziwa wa Jiji la Arusha, Arumeru na barabara ya Moshi. Tuna vyakula vya kuku wa mayai, chakula cha ng'ombe wa maziwa, mawe ya madini, dawa za kupe, chanjo zilizohifadhiwa kwenye ubaridi na mbegu za uhimilishaji. | AA6: =ROUND(6371*ACOS(MIN(1,COS(RADIANS(90-J6))*COS(RADIANS(90-$J$2))+SIN(RADIANS(90-J6))*SIN(RADIANS(90-$J$2))*COS(RADIANS(K6-$K$2)))),1) -> 458.9
A7: ST-AMS-MWZ | B7: MWZ | C7: SEL-AMS | D7: Amsterdam Group - Mwanza | E7: REG-MWZ | F7: Ilemela | G7: Kirumba | H7: Kenyatta Road, Kirumba (demo address) | I7: Near Kirumba market (demo) | J7: -2.5085 | K7: 32.9105 | L7: Regional branch | M7: FALSE | N7: +255 700 000 106 | O7: +255 700 000 106 | P7: mwanza.amsterdam@example.com | Q7: Mon-Sat 07:30-18:00; Sun closed | R7: Paulo Masanja (demo) | S7: 30 | T7: 5000 | U7: 600 | V7: TRUE | W7: TRUE | X7: FALSE | Y7: Lake Zone branch serving fish farmers around Lake Victoria as well as poultry and cattle keepers in Ilemela, Nyamagana and Misungwi. Stocks floating fish feeds and fingerlings, poultry feeds and cattle health products. | Z7: Tawi la Kanda ya Ziwa linalowahudumia wafugaji wa samaki wa Ziwa Victoria pamoja na wafugaji wa kuku na ng'ombe wa Ilemela, Nyamagana na Misungwi. Tuna vyakula vya samaki vinavyoelea, vifaranga vya samaki, vyakula vya kuku na dawa za ng'ombe. | AA7: =ROUND(6371*ACOS(MIN(1,COS(RADIANS(90-J7))*COS(RADIANS(90-$J$2))+SIN(RADIANS(90-J7))*SIN(RADIANS(90-$J$2))*COS(RADIANS(K7-$K$2)))),1) -> 836.2

Sheet Products
A1: product_id | B1: product_name | C1: brand_id | D1: brand_name | E1: producer_id | F1: top_category_id | G1: category_id | H1: category_path | I1: animal_types | J1: life_stages | K1: production_purpose | L1: form | M1: administration_route | N1: use_cases | O1: disease_target | P1: active_ingredients | Q1: crude_protein_pct | R1: inclusion_or_dosage | S1: withdrawal_meat_days | T1: withdrawal_eggs_days | U1: withdrawal_milk_days | V1: regulatory_class | W1: prescription_required | X1: cold_chain_required | Y1: storage | Z1: registration_no | AA1: capacity | AB1: power_source | AC1: breed_strain | AD1: country_of_origin | AE1: search_keywords | AF1: description_en | AG1: variant_count | AH1: is_demo_data
A2: P001 | B2: Broiler Starter Crumbs | C2: BR-SIL | D2: Silverlands | E2: BR-SIL | F2: C10 | G2: C1010 | H2: Feed > Complete feed | I2: AN-CHK | J2: LS-POU-STR | K2: broiler | L2: crumbs | M2: not_applicable | N2: early_growth|weight_gain | Q2: 22 | V2: feed | W2: FALSE | X2: FALSE | Y2: Cool, dry place below 30 C, off the floor | Z2: DEMO-FEE-0001 | AD2: Tanzania | AE2: chakula cha vifaranga|starter|broila|kuku wa nyama | AF2: Starter crumbs for broiler chicks from day 1 to about day 14. | AG2: =COUNTIF(Variants!$B:$B,A2) -> 2 | AH2: TRUE
A3: P002 | B3: Broiler Grower Pellets | C3: BR-SIL | D3: Silverlands | E3: BR-SIL | F3: C10 | G3: C1010 | H3: Feed > Complete feed | I3: AN-CHK | J3: LS-POU-GRW | K3: broiler | L3: pellets | M3: not_applicable | N3: weight_gain | Q3: 20 | V3: feed | W3: FALSE | X3: FALSE | Y3: Cool, dry place below 30 C, off the floor | Z3: DEMO-FEE-0002 | AD3: Tanzania | AE3: grower|broila|kuku wa nyama | AF3: Grower pellets for broilers from about day 15 to day 28. | AG3: =COUNTIF(Variants!$B:$B,A3) -> 2 | AH3: TRUE
A4: P003 | B4: Broiler Finisher Pellets | C4: BR-SIL | D4: Silverlands | E4: BR-SIL | F4: C10 | G4: C1010 | H4: Feed > Complete feed | I4: AN-CHK | J4: LS-POU-FIN | K4: broiler | L4: pellets | M4: not_applicable | N4: weight_gain | Q4: 19 | V4: feed | W4: FALSE | X4: FALSE | Y4: Cool, dry place below 30 C, off the floor | Z4: DEMO-FEE-0003 | AD4: Tanzania | AE4: finisher|broila|kunenepesha | AF4: Finisher pellets for broilers from day 29 to market. | AG4: =COUNTIF(Variants!$B:$B,A4) -> 2 | AH4: TRUE
A5: P004 | B5: Chick & Duck Mash | C5: BR-SHF | D5: Shamba Feeds (demo) | E5: BR-SHF | F5: C10 | G5: C1010 | H5: Feed > Complete feed | I5: AN-CHK|AN-OPO | J5: LS-POU-STR | K5: layer|improved_indigenous | L5: mash | M5: not_applicable | N5: early_growth | Q5: 20 | V5: feed | W5: FALSE | X5: FALSE | Y5: Cool, dry place below 30 C, off the floor | Z5: DEMO-FEE-0004 | AD5: Tanzania | AE5: chakula cha vifaranga|vifaranga wa mayai|bata | AF5: Starter mash for layer and improved-indigenous chicks and ducklings, 0-8 weeks. | AG5: =COUNTIF(Variants!$B:$B,A5) -> 1 | AH5: TRUE
A6: P005 | B6: Growers Mash | C6: BR-BORA | D6: Bora Feeds (demo) | E6: BR-BORA | F6: C10 | G6: C1010 | H6: Feed > Complete feed | I6: AN-CHK | J6: LS-POU-GRW | K6: layer | L6: mash | M6: not_applicable | N6: early_growth | Q6: 16 | V6: feed | W6: FALSE | X6: FALSE | Y6: Cool, dry place below 30 C, off the floor | Z6: DEMO-FEE-0005 | AD6: Tanzania | AE6: grower|leya|kuku wa mayai | AF6: Grower mash for layer pullets from 9 to 18 weeks. | AG6: =COUNTIF(Variants!$B:$B,A6) -> 2 | AH6: TRUE
A7: P006 | B7: Layers Mash | C7: BR-SIL | D7: Silverlands | E7: BR-SIL | F7: C10 | G7: C1010 | H7: Feed > Complete feed | I7: AN-CHK | J7: LS-POU-LAY | K7: layer | L7: mash | M7: not_applicable | N7: egg_production | Q7: 16.5 | V7: feed | W7: FALSE | X7: FALSE | Y7: Cool, dry place below 30 C, off the floor | Z7: DEMO-FEE-0006 | AD7: Tanzania | AE7: layers|leya|kuku wa mayai|kuongeza mayai | AF7: Complete layer ration from point of lay. | AG7: =COUNTIF(Variants!$B:$B,A7) -> 2 | AH7: TRUE
A8: P007 | B8: Kienyeji Grower Mash | C8: BR-BORA | D8: Bora Feeds (demo) | E8: BR-BORA | F8: C10 | G8: C1010 | H8: Feed > Complete feed | I8: AN-CHK | J8: LS-POU-GRW | K8: improved_indigenous | L8: mash | M8: not_applicable | N8: weight_gain | Q8: 17 | V8: feed | W8: FALSE | X8: FALSE | Y8: Cool, dry place below 30 C, off the floor | Z8: DEMO-FEE-0007 | AD8: Tanzania | AE8: kuku wa kienyeji|chotara|sasso|kuroiler | AF8: Grower mash for Sasso, Kuroiler and other improved indigenous chickens. | AG8: =COUNTIF(Variants!$B:$B,A8) -> 1 | AH8: TRUE
A9: P008 | B9: Pig Creep Pellets | C9: BR-SHF | D9: Shamba Feeds (demo) | E9: BR-SHF | F9: C10 | G9: C1010 | H9: Feed > Complete feed | I9: AN-PIG | J9: LS-PIG-CRP|LS-PIG-WEA | K9: pork | L9: pellets | M9: not_applicable | N9: early_growth | Q9: 20 | V9: feed | W9: FALSE | X9: FALSE | Y9: Cool, dry place below 30 C, off the floor | Z9: DEMO-FEE-0008 | AD9: Tanzania | AE9: nguruwe|watoto wa nguruwe|creep | AF9: Highly digestible pellets for piglets from 7 days to 2 weeks after weaning. | AG9: =COUNTIF(Variants!$B:$B,A9) -> 1 | AH9: TRUE
A10: P009 | B10: Pig Grower Pellets | C10: BR-BORA | D10: Bora Feeds (demo) | E10: BR-BORA | F10: C10 | G10: C1010 | H10: Feed > Complete feed | I10: AN-PIG | J10: LS-PIG-GRW | K10: pork | L10: pellets | M10: not_applicable | N10: weight_gain | Q10: 16 | V10: feed | W10: FALSE | X10: FALSE | Y10: Cool, dry place below 30 C, off the floor | Z10: DEMO-FEE-0009 | AD10: Tanzania | AE10: nguruwe|grower | AF10: Complete grower ration for pigs from about 25 to 60 kg live weight. | AG10: =COUNTIF(Variants!$B:$B,A10) -> 1 | AH10: TRUE
A11: P010 | B11: Sow & Weaner Meal | C11: BR-SHF | D11: Shamba Feeds (demo) | E11: BR-SHF | F11: C10 | G11: C1010 | H11: Feed > Complete feed | I11: AN-PIG | J11: LS-PIG-SOW|LS-PIG-WEA | K11: pork | L11: mash | M11: not_applicable | N11: early_growth | Q11: 16 | V11: feed | W11: FALSE | X11: FALSE | Y11: Cool, dry place below 30 C, off the floor | Z11: DEMO-FEE-0010 | AD11: Tanzania | AE11: nguruwe|mama nguruwe|sow | AF11: Meal for gestating and lactating sows and newly weaned pigs. | AG11: =COUNTIF(Variants!$B:$B,A11) -> 1 | AH11: TRUE
A12: P011 | B12: Dairy Meal | C12: BR-ULU | D12: Uluguru Agro (demo) | E12: BR-ULU | F12: C10 | G12: C1010 | H12: Feed > Complete feed | I12: AN-DCT | J12: LS-CAT-LAC | K12: dairy | L12: mash | M12: not_applicable | N12: milk_yield | Q12: 16 | V12: feed | W12: FALSE | X12: FALSE | Y12: Cool, dry place below 30 C, off the floor | Z12: DEMO-FEE-0011 | AD12: Tanzania | AE12: ng'ombe wa maziwa|dairy meal|maziwa mengi | AF12: Production ration for lactating dairy cows, fed alongside forage. | AG12: =COUNTIF(Variants!$B:$B,A12) -> 2 | AH12: TRUE
A13: P012 | B13: Calf Starter Pellets | C13: BR-ULU | D13: Uluguru Agro (demo) | E13: BR-ULU | F13: C10 | G13: C1010 | H13: Feed > Complete feed | I13: AN-DCT|AN-BCT | J13: LS-CAT-CLF | K13: dairy|beef | L13: pellets | M13: not_applicable | N13: early_growth | Q13: 20 | V13: feed | W13: FALSE | X13: FALSE | Y13: Cool, dry place below 30 C, off the floor | Z13: DEMO-FEE-0012 | AD13: Tanzania | AE13: ndama|calf | AF13: Starter pellets for calves from 1 week until weaning. | AG13: =COUNTIF(Variants!$B:$B,A13) -> 1 | AH13: TRUE
... A18: P017 | B18: Rabbit Pellets | C18: BR-SHF | D18: Shamba Feeds (demo) | E18: BR-SHF | F18: C10 | G18: C1010 | H18: Feed > Complete feed | I18: AN-OTH | J18: LS-ALL | K18: general | L18: pellets | M18: not_applicable | N18: weight_gain | Q18: 17 | V18: feed | W18: FALSE | X18: FALSE | Y18: Cool, dry place below 30 C, off the floor | Z18: DEMO-FEE-0017 | AD18: Tanzania | AE18: sungura | AF18: Complete pellets for growing and breeding rabbits. | AG18: =COUNTIF(Variants!$B:$B,A18) -> 1 | AH18: TRUE
A19: P018 | B19: Pig Protein Concentrate 20% | C19: BR-AMS | D19: Amsterdam Group | E19: BR-AMS | F19: C10 | G19: C1020 | H19: Feed > Concentrates | I19: AN-PIG | J19: LS-PIG-GRW|LS-PIG-FIN | K19: pork | L19: mash | M19: in_feed | N19: weight_gain|feed_mixing | P19: Protein, vitamins, minerals, amino acids, probiotics, enzymes, toxin binder and acidifier (per bag label) | Q19: 20 | R19: Mix with maize bran/maize as per bag label | V19: feed | W19: FALSE | X19: FALSE | Y19: Cool, dry place below 30 C, off the floor | Z19: DEMO-FEE-0018 | AD19: Tanzania | AE19: nguruwe|kontsentreti|concentrate|amsterdam feed | AF19: Amsterdam Feed high-performance pig protein concentrate. CHECK: the '20%' on the bag may be crude protein or inclusion rate; confirm with Amsterdam before publishing. | AG19: =COUNTIF(Variants!$B:$B,A19) -> 2 | AH19: TRUE
A20: P019 | B20: Broiler Concentrate 30% | C20: BR-BORA | D20: Bora Feeds (demo) | E20: BR-BORA | F20: C10 | G20: C1020 | H20: Feed > Concentrates | I20: AN-CHK | J20: LS-POU-STR|LS-POU-GRW|LS-POU-FIN | K20: broiler | L20: mash | M20: in_feed | N20: feed_mixing|weight_gain | Q20: 30 | R20: Mix with maize/maize bran as per bag label | V20: feed | W20: FALSE | X20: FALSE | Y20: Cool, dry place below 30 C, off the floor | Z20: DEMO-FEE-0019 | AD20: Tanzania | AE20: kontsentreti|broila|kuchanganya chakula | AF20: Protein concentrate for farmers mixing their own broiler feed. | AG20: =COUNTIF(Variants!$B:$B,A20) -> 1 | AH20: TRUE
A21: P020 | B21: Layers Concentrate | C21: BR-SHF | D21: Shamba Feeds (demo) | E21: BR-SHF | F21: C10 | G21: C1020 | H21: Feed > Concentrates | I21: AN-CHK | J21: LS-POU-LAY | K21: layer | L21: mash | M21: in_feed | N21: feed_mixing|egg_production | Q21: 32 | R21: Mix with maize/maize bran as per bag label | V21: feed | W21: FALSE | X21: FALSE | Y21: Cool, dry place below 30 C, off the floor | Z21: DEMO-FEE-0020 | AD21: Tanzania | AE21: kontsentreti|leya|kuku wa mayai | AF21: Concentrate for home-mixed layer rations. | AG21: =COUNTIF(Variants!$B:$B,A21) -> 1 | AH21: TRUE
A22: P021 | B22: Dairy Concentrate | C22: BR-ULU | D22: Uluguru Agro (demo) | E22: BR-ULU | F22: C10 | G22: C1020 | H22: Feed > Concentrates | I22: AN-DCT | J22: LS-CAT-LAC | K22: dairy | L22: mash | M22: in_feed | N22: feed_mixing|milk_yield | Q22: 24 | R22: Mix with maize bran as per bag label | V22: feed | W22: FALSE | X22: FALSE | Y22: Cool, dry place below 30 C, off the floor | Z22: DEMO-FEE-0021 | AD22: Tanzania | AE22: kontsentreti|ng'ombe wa maziwa | AF22: Concentrate for dairy farmers mixing with maize bran or cereal by-products. | AG22: =COUNTIF(Variants!$B:$B,A22) -> 1 | AH22: TRUE
A23: P022 | B23: Broiler Premix 2.5% | C23: BR-NYN | D23: Nyanda Nutrition (demo) | E23: BR-NYN | F23: C10 | G23: C1030 | H23: Feed > Premixes & base mixes | I23: AN-CHK | J23: LS-POU-STR|LS-POU-GRW|LS-POU-FIN | K23: broiler | L23: powder | M23: in_feed | N23: feed_mixing | P23: Vitamins, trace minerals, amino acids | R23: 2.5 kg per 100 kg of feed (per label) | V23: feed_additive | W23: FALSE | X23: FALSE | Y23: Cool, dry place below 30 C, off the floor | Z23: DEMO-FEE-0022 | AD23: Tanzania | AE23: premiksi|premix|kuchanganya chakula | AF23: Vitamin-mineral premix for on-farm feed mixing. | AG23: =COUNTIF(Variants!$B:$B,A23) -> 2 | AH23: TRUE
A24: P023 | B24: Layer Premix 2.5% | C24: BR-NYN | D24: Nyanda Nutrition (demo) | E24: BR-NYN | F24: C10 | G24: C1030 | H24: Feed > Premixes & base mixes | I24: AN-CHK | J24: LS-POU-LAY | K24: layer | L24: powder | M24: in_feed | N24: feed_mixing | P24: Vitamins, trace minerals, amino acids | R24: 2.5 kg per 100 kg of feed (per label) | V24: feed_additive | W24: FALSE | X24: FALSE | Y24: Cool, dry place below 30 C, off the floor | Z24: DEMO-FEE-0023 | AD24: Tanzania | AE24: premiksi|premix|kuchanganya chakula | AF24: Vitamin-mineral premix for on-farm feed mixing. | AG24: =COUNTIF(Variants!$B:$B,A24) -> 2 | AH24: TRUE
A25: P024 | B25: Pig Premix 2.5% | C25: BR-NYN | D25: Nyanda Nutrition (demo) | E25: BR-NYN | F25: C10 | G25: C1030 | H25: Feed > Premixes & base mixes | I25: AN-PIG | J25: LS-PIG-GRW|LS-PIG-FIN|LS-PIG-SOW | K25: pork | L25: powder | M25: in_feed | N25: feed_mixing | P25: Vitamins, trace minerals, amino acids | R25: 2.5 kg per 100 kg of feed (per label) | V25: feed_additive | W25: FALSE | X25: FALSE | Y25: Cool, dry place below 30 C, off the floor | Z25: DEMO-FEE-0024 | AD25: Tanzania | AE25: premiksi|premix|kuchanganya chakula | AF25: Vitamin-mineral premix for on-farm feed mixing. | AG25: =COUNTIF(Variants!$B:$B,A25) -> 2 | AH25: TRUE
A26: P025 | B26: Maize Bran | C26: BR-NYR | D26: Nyanda Raw Materials (demo) | E26: BR-NYR | F26: C10 | G26: C1040 | H26: Feed > Raw materials & ingredients | I26: AN-CHK|AN-PIG|AN-DCT|AN-GTS | L26: mash | M26: not_applicable | N26: feed_mixing | Q26: 10 | V26: feed | W26: FALSE | X26: FALSE | Y26: Cool, dry place below 30 C, off the floor | Z26: DEMO-FEE-0025 | AD26: Tanzania | AE26: pumba|pumba za mahindi|maize bran | AF26: Maize bran for on-farm feed mixing. | AG26: =COUNTIF(Variants!$B:$B,A26) -> 1 | AH26: TRUE
A27: P026 | B27: Sunflower Seed Cake | C27: BR-NYR | D27: Nyanda Raw Materials (demo) | E27: BR-NYR | F27: C10 | G27: C1040 | H27: Feed > Raw materials & ingredients | I27: AN-CHK|AN-PIG|AN-DCT|AN-GTS | L27: whole_grain | M27: not_applicable | N27: feed_mixing | Q27: 28 | V27: feed | W27: FALSE | X27: FALSE | Y27: Cool, dry place below 30 C, off the floor | Z27: DEMO-FEE-0026 | AD27: Tanzania | AE27: mashudu|mashudu ya alizeti|sunflower cake | AF27: Sunflower cake protein source. | AG27: =COUNTIF(Variants!$B:$B,A27) -> 1 | AH27: TRUE
A28: P027 | B28: Soybean Meal | C28: BR-NYR | D28: Nyanda Raw Materials (demo) | E28: BR-NYR | F28: C10 | G28: C1040 | H28: Feed > Raw materials & ingredients | I28: AN-CHK|AN-PIG|AN-DCT | L28: mash | M28: not_applicable | N28: feed_mixing | Q28: 44 | V28: feed | W28: FALSE | X28: FALSE | Y28: Cool, dry place below 30 C, off the floor | Z28: DEMO-FEE-0027 | AD28: Tanzania | AE28: soya|soybean meal | AF28: Solvent-extracted soybean meal. | AG28: =COUNTIF(Variants!$B:$B,A28) -> 1 | AH28: TRUE
A29: P028 | B29: Fish Meal (Dagaa) | C29: BR-NYR | D29: Nyanda Raw Materials (demo) | E29: BR-NYR | F29: C10 | G29: C1040 | H29: Feed > Raw materials & ingredients | I29: AN-CHK|AN-PIG|AN-FSH | L29: mash | M29: not_applicable | N29: feed_mixing | Q29: 55 | V29: feed | W29: FALSE | X29: FALSE | Y29: Cool, dry place below 30 C, off the floor | Z29: DEMO-FEE-0028 | AD29: Tanzania | AE29: dagaa|fish meal|unga wa samaki | AF29: Ground dagaa (Lake Victoria sardine) protein meal. | AG29: =COUNTIF(Variants!$B:$B,A29) -> 2 | AH29: TRUE
A30: P029 | B30: Feed Limestone | C30: BR-NYR | D30: Nyanda Raw Materials (demo) | E30: BR-NYR | F30: C10 | G30: C1040 | H30: Feed > Raw materials & ingredients | I30: AN-CHK|AN-DCT | L30: granules | M30: not_applicable | N30: feed_mixing|egg_production | V30: feed | W30: FALSE | X30: FALSE | Y30: Cool, dry place below 30 C, off the floor | Z30: DEMO-FEE-0029 | AD30: Tanzania | AE30: chokaa|limestone|shell grit | AF30: Calcium source for layer and dairy rations. | AG30: =COUNTIF(Variants!$B:$B,A30) -> 1 | AH30: TRUE
